Workbook
Name Old_Fold_Manor_Golf_Club_Transaction_Report_10.24.2022__2__1: 'CheshamLeyHill Transactions'!$A$1:$T$5552

Sheet Dashboard
A1: Sales Summary Report Insert dates below
A4: 45942 | B4: 45942
A6: Till Payments | D6: Total Sales | E6: Total | G6: Bar Cash Register | H6: Total
A7: Cash | B7: =SUMIFS('Mirrored Sheet'!$G:$G,'Mirrored Sheet'!$E:$E,"Cash",'Mirrored Sheet'!$V:$V,">="&$A$4,'Mirrored Sheet'!$V:$V,"<="&$B$4)+SUMIFS('Mirrored Sheet'!$G:$G,'Mirrored Sheet'!$E:$E,"Cash Change",'Mirrored Sheet'!$V:$V,">="&$A$4,'Mirrored Sheet'!$V:$V,"<="&$B$4) -> 0 | D7: Bar | E7: =SUMIFS('Mirrored Sheet'!$G:$G,'Mirrored Sheet'!$O:$O,D7,'Mirrored Sheet'!$V:$V,">="&$A$4,'Mirrored Sheet'!$V:$V,"<="&$B$4) -> 360.64 | G7: Bar
A8: Credit Card - MasterCard | B8: =SUMIFS('Mirrored Sheet'!$G:$G,'Mirrored Sheet'!$E:$E,A8,'Mirrored Sheet'!$V:$V,">="&$A$4,'Mirrored Sheet'!$V:$V,"<="&$B$4) -> 345.44 | D8: Golf Equipment & Hire | E8: =SUMIFS('Mirrored Sheet'!$G:$G,'Mirrored Sheet'!$O:$O,D8,'Mirrored Sheet'!$V:$V,">="&$A$4,'Mirrored Sheet'!$V:$V,"<="&$B$4) -> 10 | G8: Beer | H8: =SUMIFS('Mirrored Sheet'!$G:$G,'Mirrored Sheet'!$P:$P,G8,'Mirrored Sheet'!$K:$K,"Bar Cash Register",'Mirrored Sheet'!$V:$V,">="&$A$4,'Mirrored Sheet'!$V:$V,"<="&$B$4) -> 304.84
A9: Credit Card - Visa | B9: =SUMIFS('Mirrored Sheet'!$G:$G,'Mirrored Sheet'!$E:$E,A9,'Mirrored Sheet'!$V:$V,">="&$A$4,'Mirrored Sheet'!$V:$V,"<="&$B$4) -> 249.63 | D9: Green Fees | E9: =SUMIFS('Mirrored Sheet'!$G:$G,'Mirrored Sheet'!$O:$O,D9,'Mirrored Sheet'!$V:$V,">="&$A$4,'Mirrored Sheet'!$V:$V,"<="&$B$4) -> 150 | G9: Soft Drinks | H9: =SUMIFS('Mirrored Sheet'!$G:$G,'Mirrored Sheet'!$P:$P,G9,'Mirrored Sheet'!$K:$K,"Bar Cash Register",'Mirrored Sheet'!$V:$V,">="&$A$4,'Mirrored Sheet'!$V:$V,"<="&$B$4) -> 16.1
A10: Credit Card - American Express | B10: =SUMIFS('Mirrored Sheet'!$G:$G,'Mirrored Sheet'!$E:$E,A10,'Mirrored Sheet'!$V:$V,">="&$A$4,'Mirrored Sheet'!$V:$V,"<="&$B$4) -> 0 | D10: Kitchen | E10: =SUMIFS('Mirrored Sheet'!$G:$G,'Mirrored Sheet'!$O:$O,D10,'Mirrored Sheet'!$V:$V,">="&$A$4,'Mirrored Sheet'!$V:$V,"<="&$B$4) -> 92.16 | G10: Spirits | H10: =SUMIFS('Mirrored Sheet'!$G:$G,'Mirrored Sheet'!$P:$P,G10,'Mirrored Sheet'!$K:$K,"Bar Cash Register",'Mirrored Sheet'!$V:$V,">="&$A$4,'Mirrored Sheet'!$V:$V,"<="&$B$4) -> 0
A11: Custom - Credit/Debit Card | B11: =SUMIFS('Mirrored Sheet'!$G:$G,'Mirrored Sheet'!$E:$E,A11,'Mirrored Sheet'!$V:$V,">="&$A$4,'Mirrored Sheet'!$V:$V,"<="&$B$4) -> 0 | D11: Clubhouse Hire | E11: =SUMIFS('Mirrored Sheet'!$G:$G,'Mirrored Sheet'!$O:$O,D11,'Mirrored Sheet'!$V:$V,">="&$A$4,'Mirrored Sheet'!$V:$V,"<="&$B$4) -> 0 | G11: Wine | H11: =SUMIFS('Mirrored Sheet'!$G:$G,'Mirrored Sheet'!$P:$P,G11,'Mirrored Sheet'!$K:$K,"Bar Cash Register",'Mirrored Sheet'!$V:$V,">="&$A$4,'Mirrored Sheet'!$V:$V,"<="&$B$4) -> 0
A12: Wallet Sales | B12: =SUMIFS('Mirrored Sheet'!$G:$G,'Mirrored Sheet'!$E:$E,"Wallet",'Mirrored Sheet'!$V:$V,">="&$A$4,'Mirrored Sheet'!$V:$V,"<="&$B$4) -> 15 | D12: Membership | E12: =SUMIFS('Mirrored Sheet'!$G:$G,'Mirrored Sheet'!$O:$O,D12,'Mirrored Sheet'!$V:$V,">="&$A$4,'Mirrored Sheet'!$V:$V,"<="&$B$4) -> 0 | G12: Snacks | H12: =SUMIFS('Mirrored Sheet'!$G:$G,'Mirrored Sheet'!$P:$P,G12,'Mirrored Sheet'!$K:$K,"Bar Cash Register",'Mirrored Sheet'!$V:$V,">="&$A$4,'Mirrored Sheet'!$V:$V,"<="&$B$4) -> 39.7
A13: Total | B13: =SUM(B7:B12) -> 610.07 | D13: Waste and Complimentary | E13: =SUMIFS('Mirrored Sheet'!$G:$G,'Mirrored Sheet'!$O:$O,D13,'Mirrored Sheet'!$V:$V,">="&$A$4,'Mirrored Sheet'!$V:$V,"<="&$B$4) -> 0 | G13: Gas Bottles | H13: =SUMIFS('Mirrored Sheet'!$G:$G,'Mirrored Sheet'!$P:$P,G13,'Mirrored Sheet'!$K:$K,"Bar Cash Register",'Mirrored Sheet'!$V:$V,">="&$A$4,'Mirrored Sheet'!$V:$V,"<="&$B$4) -> 0
D14: Corporate | E14: =SUMIFS('Mirrored Sheet'!$G:$G,'Mirrored Sheet'!$O:$O,D14,'Mirrored Sheet'!$V:$V,">="&$A$4,'Mirrored Sheet'!$V:$V,"<="&$B$4) -> 0 | G14: Golf Equipment & Hire
A15: Wallet Top Ups | B15: =SUMIFS('Mirrored Sheet'!$G:$G,'Mirrored Sheet'!$E:$E,"Top Off Payment",'Mirrored Sheet'!$V:$V,">="&$A$4,'Mirrored Sheet'!$V:$V,"<="&$B$4) -> 0 | D15: Sundry | E15: =SUMIFS('Mirrored Sheet'!$G:$G,'Mirrored Sheet'!$O:$O,D15,'Mirrored Sheet'!$V:$V,">="&$A$4,'Mirrored Sheet'!$V:$V,"<="&$B$4) -> 0 | G15: Golf Equipment Hire | H15: =SUMIFS('Mirrored Sheet'!$G:$G,'Mirrored Sheet'!$P:$P,G15,'Mirrored Sheet'!$K:$K,"Bar Cash Register",'Mirrored Sheet'!$V:$V,">="&$A$4,'Mirrored Sheet'!$V:$V,"<="&$B$4) -> 10
D16: Grand Total | E16: =SUM(E7:E15) -> 612.8 | G16: Green Fees
D17: Plus Wallet Top Ups | E17: =E16+B15 -> 612.8 | G17: Member | H17: =SUMIFS('Mirrored Sheet'!$G:$G,'Mirrored Sheet'!$P:$P,G17,'Mirrored Sheet'!$K:$K,"Bar Cash Register",'Mirrored Sheet'!$V:$V,">="&$A$4,'Mirrored Sheet'!$V:$V,"<="&$B$4) -> 0
G18: Member Guest | H18: =SUMIFS('Mirrored Sheet'!$G:$G,'Mirrored Sheet'!$P:$P,G18,'Mirrored Sheet'!$K:$K,"Bar Cash Register",'Mirrored Sheet'!$V:$V,">="&$A$4,'Mirrored Sheet'!$V:$V,"<="&$B$4) -> 150
G19: Visitor | H19: =SUMIFS('Mirrored Sheet'!$G:$G,'Mirrored Sheet'!$P:$P,G19,'Mirrored Sheet'!$K:$K,"Bar Cash Register",'Mirrored Sheet'!$V:$V,">="&$A$4,'Mirrored Sheet'!$V:$V,"<="&$B$4) -> 0
G20: Kitchen
G21: Food & Drinks | H21: =SUMIFS('Mirrored Sheet'!$G:$G,'Mirrored Sheet'!$P:$P,G21,'Mirrored Sheet'!$K:$K,"Bar Cash Register",'Mirrored Sheet'!$V:$V,">="&$A$4,'Mirrored Sheet'!$V:$V,"<="&$B$4) -> 92.16
G22: Clubhouse Hire
G23: Clubhouse Hire | H23: =SUMIFS('Mirrored Sheet'!$G:$G,'Mirrored Sheet'!$P:$P,G23,'Mirrored Sheet'!$K:$K,"Bar Cash Register",'Mirrored Sheet'!$V:$V,">="&$A$4,'Mirrored Sheet'!$V:$V,"<="&$B$4) -> 0
G24: Membership
G25: Membership | H25: =SUMIFS('Mirrored Sheet'!$G:$G,'Mirrored Sheet'!$P:$P,G25,'Mirrored Sheet'!$K:$K,"Bar Cash Register",'Mirrored Sheet'!$V:$V,">="&$A$4,'Mirrored Sheet'!$V:$V,"<="&$B$4) -> 0
G26: Waste and Complimentary
G27: Waste and Complimentary | H27: =SUMIFS('Mirrored Sheet'!$G:$G,'Mirrored Sheet'!$P:$P,G27,'Mirrored Sheet'!$K:$K,"Bar Cash Register",'Mirrored Sheet'!$V:$V,">="&$A$4,'Mirrored Sheet'!$V:$V,"<="&$B$4) -> 0
G28: Sundry
G29: Sundry | H29: =SUMIFS('Mirrored Sheet'!$G:$G,'Mirrored Sheet'!$P:$P,G29,'Mirrored Sheet'!$K:$K,"Bar Cash Register",'Mirrored Sheet'!$V:$V,">="&$A$4,'Mirrored Sheet'!$V:$V,"<="&$B$4) -> 0
G31: Wallet Top Ups | H31: =SUMIFS('Mirrored Sheet'!$G:$G,'Mirrored Sheet'!$E:$E,"Top Off Payment",'Mirrored Sheet'!$K:$K,"Bar Cash Register",'Mirrored Sheet'!$V:$V,">="&$A$4,'Mirrored Sheet'!$V:$V,"<="&$B$4) -> 0
G35: Payment Breakdown
G36: Cash | H36: =SUMIFS('Mirrored Sheet'!$G:$G,'Mirrored Sheet'!$E:$E,"Cash",'Mirrored Sheet'!$K:$K,"Bar Cash Register",'Mirrored Sheet'!$V:$V,">="&$A$4,'Mirrored Sheet'!$V:$V,"<="&$B$4)+SUMIFS('Mirrored Sheet'!$G:$G,'Mirrored Sheet'!$E:$E,"Cash Change",'Mirrored Sheet'!$K:$K,"Bar Cash Register",'Mirrored Sheet'!$V:$V,">="&$A$4,'Mirrored Sheet'!$V:$V,"<="&$B$4) -> 0
G37: Credit Card - MasterCard | H37: =SUMIFS('Mirrored Sheet'!$G:$G,'Mirrored Sheet'!$E:$E,G37,'Mirrored Sheet'!$K:$K,"Bar Cash Register",'Mirrored Sheet'!$V:$V,">="&$A$4,'Mirrored Sheet'!$V:$V,"<="&$B$4) -> 345.44
G38: Credit Card - Visa | H38: =SUMIFS('Mirrored Sheet'!$G:$G,'Mirrored Sheet'!$E:$E,G38,'Mirrored Sheet'!$K:$K,"Bar Cash Register",'Mirrored Sheet'!$V:$V,">="&$A$4,'Mirrored Sheet'!$V:$V,"<="&$B$4) -> 249.63
G39: Credit Card - American Express | H39: =SUMIFS('Mirrored Sheet'!$G:$G,'Mirrored Sheet'!$E:$E,G39,'Mirrored Sheet'!$K:$K,"Bar Cash Register",'Mirrored Sheet'!$V:$V,">="&$A$4,'Mirrored Sheet'!$V:$V,"<="&$B$4) -> 0
G40: Custom - Credit/Debit Card | H40: =SUMIFS('Mirrored Sheet'!$G:$G,'Mirrored Sheet'!$E:$E,G40,'Mirrored Sheet'!$K:$K,"Bar Cash Register",'Mirrored Sheet'!$V:$V,">="&$A$4,'Mirrored Sheet'!$V:$V,"<="&$B$4) -> 0
G41: Wallet Sales | H41: =SUMIFS('Mirrored Sheet'!$G:$G,'Mirrored Sheet'!$E:$E,"Wallet",'Mirrored Sheet'!$K:$K,"Bar Cash Register",'Mirrored Sheet'!$V:$V,">="&$A$4,'Mirrored Sheet'!$V:$V,"<="&$B$4) -> 15
G42: Total | H42: =SUM(H36:H41) -> 610.07

Sheet CheshamLeyHill Transactions
A1: Location | B1: Order_Number | C1: Date_Completed | D1: Item_Type | E1: Item | F1: SKU | G1: Amount | H1: Quantity | I1: Location | J1: Area | K1: Cash_Register | L1: Cash_Register_Status | M1: Cash_Register_Open_Date | N1: Cash_Register_Close_Date | O1: Department | P1: Category | Q1: Sub_Category | R1: GL_Code | S1: GL_Code_Description | T1: Customer
A2: Chesham & Ley Hill Golf Club | B2: 100229942881 | C2: 10/12/2025 9:28 AM | D2: Green Fees | E2: Greenkeepers Challenge - Greenkeepers Challenge Visitor - 18 | G2: 15 | H2: 1 | I2: Chesham & Ley Hill Golf Club | J2: Chesham & Ley Hill GC | K2: Bar Cash Register | L2: Open | M2: 8/13/2025 7:01 PM | O2: Green Fees | P2: Member Guest | Q2: Greenkeepers Challenge - Greenkeepers Challenge Visitor - 18 | S2: Member Guest | T2: Walk-in Customer
A3: Chesham & Ley Hill Golf Club | B3: 100229942881 | C3: 10/12/2025 9:28 AM | D3: Payment Item - Visa | E3: Credit Card - Visa | G3: 15 | I3: Chesham & Ley Hill Golf Club | J3: Chesham & Ley Hill GC | K3: Bar Cash Register | L3: Open | M3: 8/13/2025 7:01 PM | S3: Visa | T3: Walk-in Customer
A4: Chesham & Ley Hill Golf Club | B4: 100229942884 | C4: 10/12/2025 9:29 AM | D4: Green Fees | E4: Greenkeepers Challenge - Greenkeepers Challenge Visitor - 18 | G4: 15 | H4: 1 | I4: Chesham & Ley Hill Golf Club | J4: Chesham & Ley Hill GC | K4: Bar Cash Register | L4: Open | M4: 8/13/2025 7:01 PM | O4: Green Fees | P4: Member Guest | Q4: Greenkeepers Challenge - Greenkeepers Challenge Visitor - 18 | S4: Member Guest | T4: Walk-in Customer
A5: Chesham & Ley Hill Golf Club | B5: 100229942884 | C5: 10/12/2025 9:29 AM | D5: Payment Item - Visa | E5: Credit Card - Visa | G5: 15 | I5: Chesham & Ley Hill Golf Club | J5: Chesham & Ley Hill GC | K5: Bar Cash Register | L5: Open | M5: 8/13/2025 7:01 PM | S5: Visa | T5: Walk-in Customer
A6: Chesham & Ley Hill Golf Club | B6: 100229942893 | C6: 10/12/2025 9:30 AM | D6: Green Fees | E6: Greenkeepers Challenge - Greenkeepers Challenge Visitor - 18 | G6: 15 | H6: 1 | I6: Chesham & Ley Hill Golf Club | J6: Chesham & Ley Hill GC | K6: Bar Cash Register | L6: Open | M6: 8/13/2025 7:01 PM | O6: Green Fees | P6: Member Guest | Q6: Greenkeepers Challenge - Greenkeepers Challenge Visitor - 18 | S6: Member Guest | T6: Walk-in Customer
A7: Chesham & Ley Hill Golf Club | B7: 100229942893 | C7: 10/12/2025 9:30 AM | D7: Payment Item - MasterCard | E7: Credit Card - MasterCard | G7: 15 | I7: Chesham & Ley Hill Golf Club | J7: Chesham & Ley Hill GC | K7: Bar Cash Register | L7: Open | M7: 8/13/2025 7:01 PM | S7: MasterCard | T7: Walk-in Customer
A8: Chesham & Ley Hill Golf Club | B8: 100229942981 | C8: 10/12/2025 9:40 AM | D8: Green Fees | E8: Greenkeepers Challenge - Greenkeepers Challenge Visitor - 18 | G8: 15 | H8: 1 | I8: Chesham & Ley Hill Golf Club | J8: Chesham & Ley Hill GC | K8: Bar Cash Register | L8: Open | M8: 8/13/2025 7:01 PM | O8: Green Fees | P8: Member Guest | Q8: Greenkeepers Challenge - Greenkeepers Challenge Visitor - 18 | S8: Member Guest | T8: Walk-in Customer
A9: Chesham & Ley Hill Golf Club | B9: 100229942981 | C9: 10/12/2025 9:40 AM | D9: Payment Item - Visa | E9: Credit Card - Visa | G9: 15 | I9: Chesham & Ley Hill Golf Club | J9: Chesham & Ley Hill GC | K9: Bar Cash Register | L9: Open | M9: 8/13/2025 7:01 PM | S9: Visa | T9: Walk-in Customer
A10: Chesham & Ley Hill Golf Club | B10: 100229942997 | C10: 10/12/2025 9:41 AM | D10: Green Fees | E10: Greenkeepers Challenge - Greenkeepers Challenge Visitor - 18 | G10: 15 | H10: 1 | I10: Chesham & Ley Hill Golf Club | J10: Chesham & Ley Hill GC | K10: Bar Cash Register | L10: Open | M10: 8/13/2025 7:01 PM | O10: Green Fees | P10: Member Guest | Q10: Greenkeepers Challenge - Greenkeepers Challenge Visitor - 18 | S10: Member Guest | T10: Walk-in Customer
A11: Chesham & Ley Hill Golf Club | B11: 100229942997 | C11: 10/12/2025 9:41 AM | D11: Payment Item - MasterCard | E11: Credit Card - MasterCard | G11: 15 | I11: Chesham & Ley Hill Golf Club | J11: Chesham & Ley Hill GC | K11: Bar Cash Register | L11: Open | M11: 8/13/2025 7:01 PM | S11: MasterCard | T11: Walk-in Customer
A12: Chesham & Ley Hill Golf Club | B12: 100229942999 | C12: 10/12/2025 9:42 AM | D12: Green Fees | E12: Greenkeepers Challenge - Greenkeepers Challenge Visitor - 18 | G12: 15 | H12: 1 | I12: Chesham & Ley Hill Golf Club | J12: Chesham & Ley Hill GC | K12: Bar Cash Register | L12: Open | M12: 8/13/2025 7:01 PM | O12: Green Fees | P12: Member Guest | Q12: Greenkeepers Challenge - Greenkeepers Challenge Visitor - 18 | S12: Member Guest | T12: Walk-in Customer
A13: Chesham & Ley Hill Golf Club | B13: 100229942999 | C13: 10/12/2025 9:42 AM | D13: Payment Item - MasterCard | E13: Credit Card - MasterCard | G13: 15 | I13: Chesham & Ley Hill Golf Club | J13: Chesham & Ley Hill GC | K13: Bar Cash Register | L13: Open | M13: 8/13/2025 7:01 PM | S13: MasterCard | T13: Walk-in Customer
A14: Chesham & Ley Hill Golf Club | B14: 100229943011 | C14: 10/12/2025 9:43 AM | D14: Green Fees | E14: Greenkeepers Challenge - Greenkeepers Challenge Visitor - 18 | G14: 15 | H14: 1 | I14: Chesham & Ley Hill Golf Club | J14: Chesham & Ley Hill GC | K14: Bar Cash Register | L14: Open | M14: 8/13/2025 7:01 PM | O14: Green Fees | P14: Member Guest | Q14: Greenkeepers Challenge - Greenkeepers Challenge Visitor - 18 | S14: Member Guest | T14: Walk-in Customer
A15: Chesham & Ley Hill Golf Club | B15: 100229943011 | C15: 10/12/2025 9:43 AM | D15: Payment Item - MasterCard | E15: Credit Card - MasterCard | G15: 15 | I15: Chesham & Ley Hill Golf Club | J15: Chesham & Ley Hill GC | K15: Bar Cash Register | L15: Open | M15: 8/13/2025 7:01 PM | S15: MasterCard | T15: Walk-in Customer
A16: Chesham & Ley Hill Golf Club | B16: 100229943014 | C16: 10/12/2025 9:44 AM | D16: Green Fees | E16: Greenkeepers Challenge - Greenkeepers Challenge Visitor - 18 | G16: 15 | H16: 1 | I16: Chesham & Ley Hill Golf Club | J16: Chesham & Ley Hill GC | K16: Bar Cash Register | L16: Open | M16: 8/13/2025 7:01 PM | O16: Green Fees | P16: Member Guest | Q16: Greenkeepers Challenge - Greenkeepers Challenge Visitor - 18 | S16: Member Guest | T16: Walk-in Customer
A17: Chesham & Ley Hill Golf Club | B17: 100229943014 | C17: 10/12/2025 9:44 AM | D17: Payment Item - MasterCard | E17: Credit Card - MasterCard | G17: 15 | I17: Chesham & Ley Hill Golf Club | J17: Chesham & Ley Hill GC | K17: Bar Cash Register | L17: Open | M17: 8/13/2025 7:01 PM | S17: MasterCard | T17: Walk-in Customer
A18: Chesham & Ley Hill Golf Club | B18: 100229943018 | C18: 10/12/2025 9:44 AM | D18: Green Fees | E18: Greenkeepers Challenge - Greenkeepers Challenge Visitor - 18 | G18: 15 | H18: 1 | I18: Chesham & Ley Hill Golf Club | J18: Chesham & Ley Hill GC | K18: Bar Cash Register | L18: Open | M18: 8/13/2025 7:01 PM | O18: Green Fees | P18: Member Guest | Q18: Greenkeepers Challenge - Greenkeepers Challenge Visitor - 18 | S18: Member Guest | T18: Walk-in Customer
A19: Chesham & Ley Hill Golf Club | B19: 100229943018 | C19: 10/12/2025 9:44 AM | D19: Payment Item - Visa | E19: Credit Card - Visa | G19: 15 | I19: Chesham & Ley Hill Golf Club | J19: Chesham & Ley Hill GC | K19: Bar Cash Register | L19: Open | M19: 8/13/2025 7:01 PM | S19: Visa | T19: Walk-in Customer
A20: Chesham & Ley Hill Golf Club | B20: 100229943020 | C20: 10/12/2025 9:46 AM | D20: Product | E20: Clubs Hire | F20: 12976154 | G20: 10 | H20: 1 | I20: Chesham & Ley Hill Golf Club | J20: Chesham & Ley Hill GC | K20: Bar Cash Register | L20: Open | M20: 8/13/2025 7:01 PM | O20: Golf Equipment & Hire | P20: Golf Equipment Hire | Q20: Golf Equipment & Hire | R20: G | S20: Golf Equipment & Hire | T20: Walk-in Customer
A21: Chesham & Ley Hill Golf Club | B21: 100229943020 | C21: 10/12/2025 9:46 AM | D21: Green Fees | E21: Greenkeepers Challenge - Greenkeepers Challenge Visitor - 18 | G21: 15 | H21: 1 | I21: Chesham & Ley Hill Golf Club | J21: Chesham & Ley Hill GC | K21: Bar Cash Register | L21: Open | M21: 8/13/2025 7:01 PM | O21: Green Fees | P21: Member Guest | Q21: Greenkeepers Challenge - Greenkeepers Challenge Visitor - 18 | S21: Member Guest | T21: Walk-in Customer
A22: Chesham & Ley Hill Golf Club | B22: 100229943020 | C22: 10/12/2025 9:46 AM | D22: Tax | E22: VAT | G22: 1.67 | I22: Chesham & Ley Hill Golf Club | J22: Chesham & Ley Hill GC | K22: Bar Cash Register | L22: Open | M22: 8/13/2025 7:01 PM | T22: Walk-in Customer
A23: Chesham & Ley Hill Golf Club | B23: 100229943020 | C23: 10/12/2025 9:46 AM | D23: Payment Item - Visa | E23: Credit Card - Visa | G23: 25 | I23: Chesham & Ley Hill Golf Club | J23: Chesham & Ley Hill GC | K23: Bar Cash Register | L23: Open | M23: 8/13/2025 7:01 PM | S23: Visa | T23: Walk-in Customer
A24: Chesham & Ley Hill Golf Club | B24: 100229943215 | C24: 10/12/2025 10:08 AM | D24: Product | E24: Bap Bacon | F24: 12975978 | G24: 4.54 | H24: 1 | I24: Chesham & Ley Hill Golf Club | J24: Chesham & Ley Hill GC | K24: Bar Cash Register | L24: Open | M24: 8/13/2025 7:01 PM | O24: Kitchen | P24: Food & Drinks | Q24: Food & Drinks | R24: K | S24: Food & Drinks | T24: Paul Watkins
A25: Chesham & Ley Hill Golf Club | B25: 100229943215 | C25: 10/12/2025 10:08 AM | D25: Product | E25: Bap Bacon | F25: 12975978 | G25: 4.54 | H25: 1 | I25: Chesham & Ley Hill Golf Club | J25: Chesham & Ley Hill GC | K25: Bar Cash Register | L25: Open | M25: 8/13/2025 7:01 PM | O25: Kitchen | P25: Food & Drinks | Q25: Food & Drinks | R25: K | S25: Food & Drinks | T25: Paul Watkins
A26: Chesham & Ley Hill Golf Club | B26: 100229943215 | C26: 10/12/2025 10:08 AM | D26: Product | E26: Bap Bacon | F26: 12975978 | G26: 4.54 | H26: 1 | I26: Chesham & Ley Hill Golf Club | J26: Chesham & Ley Hill GC | K26: Bar Cash Register | L26: Open | M26: 8/13/2025 7:01 PM | O26: Kitchen | P26: Food & Drinks | Q26: Food & Drinks | R26: K | S26: Food & Drinks | T26: Paul Watkins
A27: Chesham & Ley Hill Golf Club | B27: 100229943215 | C27: 10/12/2025 10:08 AM | D27: Product | E27: Bap Bacon | F27: 12975978 | G27: 4.54 | H27: 1 | I27: Chesham & Ley Hill Golf Club | J27: Chesham & Ley Hill GC | K27: Bar Cash Register | L27: Open | M27: 8/13/2025 7:01 PM | O27: Kitchen | P27: Food & Drinks | Q27: Food & Drinks | R27: K | S27: Food & Drinks | T27: Paul Watkins
A28: Chesham & Ley Hill Golf Club | B28: 100229943215 | C28: 10/12/2025 10:08 AM | D28: Product | E28: Bap Bacon | F28: 12975978 | G28: 4.54 | H28: 1 | I28: Chesham & Ley Hill Golf Club | J28: Chesham & Ley Hill GC | K28: Bar Cash Register | L28: Open | M28: 8/13/2025 7:01 PM | O28: Kitchen | P28: Food & Drinks | Q28: Food & Drinks | R28: K | S28: Food & Drinks | T28: Paul Watkins
A29: Chesham & Ley Hill Golf Club | B29: 100229943215 | C29: 10/12/2025 10:08 AM | D29: Product | E29: Bap Bacon | F29: 12975978 | G29: 4.54 | H29: 1 | I29: Chesham & Ley Hill Golf Club | J29: Chesham & Ley Hill GC | K29: Bar Cash Register | L29: Open | M29: 8/13/2025 7:01 PM | O29: Kitchen | P29: Food & Drinks | Q29: Food & Drinks | R29: K | S29: Food & Drinks | T29: Paul Watkins
A30: Chesham & Ley Hill Golf Club | B30: 100229943215 | C30: 10/12/2025 10:08 AM | D30: Product | E30: Bap Bacon | F30: 12975978 | G30: 4.54 | H30: 1 | I30: Chesham & Ley Hill Golf Club | J30: Chesham & Ley Hill GC | K30: Bar Cash Register | L30: Open | M30: 8/13/2025 7:01 PM | O30: Kitchen | P30: Food & Drinks | Q30: Food & Drinks | R30: K | S30: Food & Drinks | T30: Paul Watkins
A31: Chesham & Ley Hill Golf Club | B31: 100229943215 | C31: 10/12/2025 10:08 AM | D31: Product | E31: Pot of Coffee | F31: 12975971 | G31: 6.82 | H31: 1 | I31: Chesham & Ley Hill Golf Club | J31: Chesham & Ley Hill GC | K31: Bar Cash Register | L31: Open | M31: 8/13/2025 7:01 PM | O31: Kitchen | P31: Food & Drinks | Q31: Food & Drinks | R31: K | S31: Food & Drinks | T31: Paul Watkins
A32: Chesham & Ley Hill Golf Club | B32: 100229943215 | C32: 10/12/2025 10:08 AM | D32: Product | E32: Pot of Coffee | F32: 12975971 | G32: 6.82 | H32: 1 | I32: Chesham & Ley Hill Golf Club | J32: Chesham & Ley Hill GC | K32: Bar Cash Register | L32: Open | M32: 8/13/2025 7:01 PM | O32: Kitchen | P32: Food & Drinks | Q32: Food & Drinks | R32: K | S32: Food & Drinks | T32: Paul Watkins
A33: Chesham & Ley Hill Golf Club | B33: 100229943215 | C33: 10/12/2025 10:08 AM | D33: Product | E33: Pot of Coffee | F33: 12975971 | G33: 6.82 | H33: 1 | I33: Chesham & Ley Hill Golf Club | J33: Chesham & Ley Hill GC | K33: Bar Cash Register | L33: Open | M33: 8/13/2025 7:01 PM | O33: Kitchen | P33: Food & Drinks | Q33: Food & Drinks | R33: K | S33: Food & Drinks | T33: Paul Watkins
A34: Chesham & Ley Hill Golf Club | B34: 100229943215 | C34: 10/12/2025 10:08 AM | D34: Product | E34: Pot of Coffee | F34: 12975971 | G34: 6.82 | H34: 1 | I34: Chesham & Ley Hill Golf Club | J34: Chesham & Ley Hill GC | K34: Bar Cash Register | L34: Open | M34: 8/13/2025 7:01 PM | O34: Kitchen | P34: Food & Drinks | Q34: Food & Drinks | R34: K | S34: Food & Drinks | T34: Paul Watkins
A35: Chesham & Ley Hill Golf Club | B35: 100229943215 | C35: 10/12/2025 10:08 AM | D35: Tax | E35: VAT | G35: 9.88 | I35: Chesham & Ley Hill Golf Club | J35: Chesham & Ley Hill GC | K35: Bar Cash Register | L35: Open | M35: 8/13/2025 7:01 PM | T35: Paul Watkins
A36: Chesham & Ley Hill Golf Club | B36: 100229943215 | C36: 10/12/2025 10:08 AM | D36: Payment Item - MasterCard | E36: Credit Card - MasterCard | G36: 59.06 | I36: Chesham & Ley Hill Golf Club | J36: Chesham & Ley Hill GC | K36: Bar Cash Register | L36: Open | M36: 8/13/2025 7:01 PM | S36: MasterCard | T36: Paul Watkins
A37: Chesham & Ley Hill Golf Club | B37: 100229944066 | C37: 10/12/2025 11:52 AM | D37: Product | E37: Peroni Nastro Azzurro | F37: 12976070 | G37: 3.64 | H37: 1 | I37: Chesham & Ley Hill Golf Club | J37: Chesham & Ley Hill GC | K37: Bar Cash Register | L37: Open | M37: 8/13/2025 7:01 PM | O37: Bar | P37: Beer | Q37: Bottle (Bar) | R37: B | S37: Bottle (Bar) | T37: Robin Cusdin
A38: Chesham & Ley Hill Golf Club | B38: 100229944066 | C38: 10/12/2025 11:52 AM | D38: Product | E38: Peroni Nastro Azzurro | F38: 12976070 | G38: 3.64 | H38: 1 | I38: Chesham & Ley Hill Golf Club | J38: Chesham & Ley Hill GC | K38: Bar Cash Register | L38: Open | M38: 8/13/2025 7:01 PM | O38: Bar | P38: Beer | Q38: Bottle (Bar) | R38: B | S38: Bottle (Bar) | T38: Robin Cusdin
A39: Chesham & Ley Hill Golf Club | B39: 100229944066 | C39: 10/12/2025 11:52 AM | D39: Product | E39: Peroni Nastro Azzurro | F39: 12976070 | G39: 3.64 | H39: 1 | I39: Chesham & Ley Hill Golf Club | J39: Chesham & Ley Hill GC | K39: Bar Cash Register | L39: Open | M39: 8/13/2025 7:01 PM | O39: Bar | P39: Beer | Q39: Bottle (Bar) | R39: B | S39: Bottle (Bar) | T39: Robin Cusdin
A40: Chesham & Ley Hill Golf Club | B40: 100229944066 | C40: 10/12/2025 11:52 AM | D40: Product | E40: Peroni Nastro Azzurro | F40: 12976070 | G40: 3.64 | H40: 1 | I40: Chesham & Ley Hill Golf Club | J40: Chesham & Ley Hill GC | K40: Bar Cash Register | L40: Open | M40: 8/13/2025 7:01 PM | O40: Bar | P40: Beer | Q40: Bottle (Bar) | R40: B | S40: Bottle (Bar) | T40: Robin Cusdin
...

Sheet Product by payment method
A1: Till by payment method by department

Sheet Mirrored Sheet
A1: ='CheshamLeyHill Transactions'!A1 -> Location | B1: ='CheshamLeyHill Transactions'!B1 -> Order_Number | C1: ='CheshamLeyHill Transactions'!C1 -> Date_Completed | D1: ='CheshamLeyHill Transactions'!D1 -> Item_Type | E1: ='CheshamLeyHill Transactions'!E1 -> Item | F1: ='CheshamLeyHill Transactions'!F1 -> SKU | G1: ='CheshamLeyHill Transactions'!G1 -> Amount | H1: ='CheshamLeyHill Transactions'!H1 -> Quantity | ... T1: ='CheshamLeyHill Transactions'!T1 -> Customer | U1: Date Helper | V1: Date Helper
A2: ='CheshamLeyHill Transactions'!A2 -> Chesham & Ley Hill Golf Club | B2: ='CheshamLeyHill Transactions'!B2 -> 100229942881 | C2: ='CheshamLeyHill Transactions'!C2 -> 10/12/2025 9:28 AM | D2: ='CheshamLeyHill Transactions'!D2 -> Green Fees | E2: ='CheshamLeyHill Transactions'!E2 -> Greenkeepers Challenge - Greenkeepers Challenge Visitor - 18 | F2: ='CheshamLeyHill Transactions'!F2 -> 0 | G2: ='CheshamLeyHill Transactions'!G2 -> 15 | H2: ='CheshamLeyHill Transactions'!H2 -> 1 | ... T2: ='CheshamLeyHill Transactions'!T2 -> Walk-in Customer | U2: =SUBSTITUTE(MID(C2,FIND("/",C2)+1,2)&"/"&LEFT(C2,2)&MID(C2,FIND("/",C2,4),5),"//","/") -> 12/10/2025 | V2: =DATEVALUE(U2) -> 45942
A3: ='CheshamLeyHill Transactions'!A3 -> Chesham & Ley Hill Golf Club | B3: ='CheshamLeyHill Transactions'!B3 -> 100229942881 | C3: ='CheshamLeyHill Transactions'!C3 -> 10/12/2025 9:28 AM | D3: ='CheshamLeyHill Transactions'!D3 -> Payment Item - Visa | E3: ='CheshamLeyHill Transactions'!E3 -> Credit Card - Visa | F3: ='CheshamLeyHill Transactions'!F3 -> 0 | G3: ='CheshamLeyHill Transactions'!G3 -> 15 | H3: ='CheshamLeyHill Transactions'!H3 -> 0 | ... T3: ='CheshamLeyHill Transactions'!T3 -> Walk-in Customer | U3: =SUBSTITUTE(MID(C3,FIND("/",C3)+1,2)&"/"&LEFT(C3,2)&MID(C3,FIND("/",C3,4),5),"//","/") -> 12/10/2025 | V3: =DATEVALUE(U3) -> 45942
A4: ='CheshamLeyHill Transactions'!A4 -> Chesham & Ley Hill Golf Club | B4: ='CheshamLeyHill Transactions'!B4 -> 100229942884 | C4: ='CheshamLeyHill Transactions'!C4 -> 10/12/2025 9:29 AM | D4: ='CheshamLeyHill Transactions'!D4 -> Green Fees | E4: ='CheshamLeyHill Transactions'!E4 -> Greenkeepers Challenge - Greenkeepers Challenge Visitor - 18 | F4: ='CheshamLeyHill Transactions'!F4 -> 0 | G4: ='CheshamLeyHill Transactions'!G4 -> 15 | H4: ='CheshamLeyHill Transactions'!H4 -> 1 | ... T4: ='CheshamLeyHill Transactions'!T4 -> Walk-in Customer | U4: =SUBSTITUTE(MID(C4,FIND("/",C4)+1,2)&"/"&LEFT(C4,2)&MID(C4,FIND("/",C4,4),5),"//","/") -> 12/10/2025 | V4: =DATEVALUE(U4) -> 45942
A5: ='CheshamLeyHill Transactions'!A5 -> Chesham & Ley Hill Golf Club | B5: ='CheshamLeyHill Transactions'!B5 -> 100229942884 | C5: ='CheshamLeyHill Transactions'!C5 -> 10/12/2025 9:29 AM | D5: ='CheshamLeyHill Transactions'!D5 -> Payment Item - Visa | E5: ='CheshamLeyHill Transactions'!E5 -> Credit Card - Visa | F5: ='CheshamLeyHill Transactions'!F5 -> 0 | G5: ='CheshamLeyHill Transactions'!G5 -> 15 | H5: ='CheshamLeyHill Transactions'!H5 -> 0 | ... T5: ='CheshamLeyHill Transactions'!T5 -> Walk-in Customer | U5: =SUBSTITUTE(MID(C5,FIND("/",C5)+1,2)&"/"&LEFT(C5,2)&MID(C5,FIND("/",C5,4),5),"//","/") -> 12/10/2025 | V5: =DATEVALUE(U5) -> 45942
A6: ='CheshamLeyHill Transactions'!A6 -> Chesham & Ley Hill Golf Club | B6: ='CheshamLeyHill Transactions'!B6 -> 100229942893 | C6: ='CheshamLeyHill Transactions'!C6 -> 10/12/2025 9:30 AM | D6: ='CheshamLeyHill Transactions'!D6 -> Green Fees | E6: ='CheshamLeyHill Transactions'!E6 -> Greenkeepers Challenge - Greenkeepers Challenge Visitor - 18 | F6: ='CheshamLeyHill Transactions'!F6 -> 0 | G6: ='CheshamLeyHill Transactions'!G6 -> 15 | H6: ='CheshamLeyHill Transactions'!H6 -> 1 | ... T6: ='CheshamLeyHill Transactions'!T6 -> Walk-in Customer | U6: =SUBSTITUTE(MID(C6,FIND("/",C6)+1,2)&"/"&LEFT(C6,2)&MID(C6,FIND("/",C6,4),5),"//","/") -> 12/10/2025 | V6: =DATEVALUE(U6) -> 45942
A7: ='CheshamLeyHill Transactions'!A7 -> Chesham & Ley Hill Golf Club | B7: ='CheshamLeyHill Transactions'!B7 -> 100229942893 | C7: ='CheshamLeyHill Transactions'!C7 -> 10/12/2025 9:30 AM | D7: ='CheshamLeyHill Transactions'!D7 -> Payment Item - MasterCard | E7: ='CheshamLeyHill Transactions'!E7 -> Credit Card - MasterCard | F7: ='CheshamLeyHill Transactions'!F7 -> 0 | G7: ='CheshamLeyHill Transactions'!G7 -> 15 | H7: ='CheshamLeyHill Transactions'!H7 -> 0 | ... T7: ='CheshamLeyHill Transactions'!T7 -> Walk-in Customer | U7: =SUBSTITUTE(MID(C7,FIND("/",C7)+1,2)&"/"&LEFT(C7,2)&MID(C7,FIND("/",C7,4),5),"//","/") -> 12/10/2025 | V7: =DATEVALUE(U7) -> 45942
A8: ='CheshamLeyHill Transactions'!A8 -> Chesham & Ley Hill Golf Club | B8: ='CheshamLeyHill Transactions'!B8 -> 100229942981 | C8: ='CheshamLeyHill Transactions'!C8 -> 10/12/2025 9:40 AM | D8: ='CheshamLeyHill Transactions'!D8 -> Green Fees | E8: ='CheshamLeyHill Transactions'!E8 -> Greenkeepers Challenge - Greenkeepers Challenge Visitor - 18 | F8: ='CheshamLeyHill Transactions'!F8 -> 0 | G8: ='CheshamLeyHill Transactions'!G8 -> 15 | H8: ='CheshamLeyHill Transactions'!H8 -> 1 | ... T8: ='CheshamLeyHill Transactions'!T8 -> Walk-in Customer | U8: =SUBSTITUTE(MID(C8,FIND("/",C8)+1,2)&"/"&LEFT(C8,2)&MID(C8,FIND("/",C8,4),5),"//","/") -> 12/10/2025 | V8: =DATEVALUE(U8) -> 45942
A9: ='CheshamLeyHill Transactions'!A9 -> Chesham & Ley Hill Golf Club | B9: ='CheshamLeyHill Transactions'!B9 -> 100229942981 | C9: ='CheshamLeyHill Transactions'!C9 -> 10/12/2025 9:40 AM | D9: ='CheshamLeyHill Transactions'!D9 -> Payment Item - Visa | E9: ='CheshamLeyHill Transactions'!E9 -> Credit Card - Visa | F9: ='CheshamLeyHill Transactions'!F9 -> 0 | G9: ='CheshamLeyHill Transactions'!G9 -> 15 | H9: ='CheshamLeyHill Transactions'!H9 -> 0 | ... T9: ='CheshamLeyHill Transactions'!T9 -> Walk-in Customer | U9: =SUBSTITUTE(MID(C9,FIND("/",C9)+1,2)&"/"&LEFT(C9,2)&MID(C9,FIND("/",C9,4),5),"//","/") -> 12/10/2025 | V9: =DATEVALUE(U9) -> 45942
A10: ='CheshamLeyHill Transactions'!A10 -> Chesham & Ley Hill Golf Club | B10: ='CheshamLeyHill Transactions'!B10 -> 100229942997 | C10: ='CheshamLeyHill Transactions'!C10 -> 10/12/2025 9:41 AM | D10: ='CheshamLeyHill Transactions'!D10 -> Green Fees | E10: ='CheshamLeyHill Transactions'!E10 -> Greenkeepers Challenge - Greenkeepers Challenge Visitor - 18 | F10: ='CheshamLeyHill Transactions'!F10 -> 0 | G10: ='CheshamLeyHill Transactions'!G10 -> 15 | H10: ='CheshamLeyHill Transactions'!H10 -> 1 | ... T10: ='CheshamLeyHill Transactions'!T10 -> Walk-in Customer | U10: =SUBSTITUTE(MID(C10,FIND("/",C10)+1,2)&"/"&LEFT(C10,2)&MID(C10,FIND("/",C10,4),5),"//","/") -> 12/10/2025 | V10: =DATEVALUE(U10) -> 45942
A11: ='CheshamLeyHill Transactions'!A11 -> Chesham & Ley Hill Golf Club | B11: ='CheshamLeyHill Transactions'!B11 -> 100229942997 | C11: ='CheshamLeyHill Transactions'!C11 -> 10/12/2025 9:41 AM | D11: ='CheshamLeyHill Transactions'!D11 -> Payment Item - MasterCard | E11: ='CheshamLeyHill Transactions'!E11 -> Credit Card - MasterCard | F11: ='CheshamLeyHill Transactions'!F11 -> 0 | G11: ='CheshamLeyHill Transactions'!G11 -> 15 | H11: ='CheshamLeyHill Transactions'!H11 -> 0 | ... T11: ='CheshamLeyHill Transactions'!T11 -> Walk-in Customer | U11: =SUBSTITUTE(MID(C11,FIND("/",C11)+1,2)&"/"&LEFT(C11,2)&MID(C11,FIND("/",C11,4),5),"//","/") -> 12/10/2025 | V11: =DATEVALUE(U11) -> 45942
A12: ='CheshamLeyHill Transactions'!A12 -> Chesham & Ley Hill Golf Club | B12: ='CheshamLeyHill Transactions'!B12 -> 100229942999 | C12: ='CheshamLeyHill Transactions'!C12 -> 10/12/2025 9:42 AM | D12: ='CheshamLeyHill Transactions'!D12 -> Green Fees | E12: ='CheshamLeyHill Transactions'!E12 -> Greenkeepers Challenge - Greenkeepers Challenge Visitor - 18 | F12: ='CheshamLeyHill Transactions'!F12 -> 0 | G12: ='CheshamLeyHill Transactions'!G12 -> 15 | H12: ='CheshamLeyHill Transactions'!H12 -> 1 | ... T12: ='CheshamLeyHill Transactions'!T12 -> Walk-in Customer | U12: =SUBSTITUTE(MID(C12,FIND("/",C12)+1,2)&"/"&LEFT(C12,2)&MID(C12,FIND("/",C12,4),5),"//","/") -> 12/10/2025 | V12: =DATEVALUE(U12) -> 45942
A13: ='CheshamLeyHill Transactions'!A13 -> Chesham & Ley Hill Golf Club | B13: ='CheshamLeyHill Transactions'!B13 -> 100229942999 | C13: ='CheshamLeyHill Transactions'!C13 -> 10/12/2025 9:42 AM | D13: ='CheshamLeyHill Transactions'!D13 -> Payment Item - MasterCard | E13: ='CheshamLeyHill Transactions'!E13 -> Credit Card - MasterCard | F13: ='CheshamLeyHill Transactions'!F13 -> 0 | G13: ='CheshamLeyHill Transactions'!G13 -> 15 | H13: ='CheshamLeyHill Transactions'!H13 -> 0 | ... T13: ='CheshamLeyHill Transactions'!T13 -> Walk-in Customer | U13: =SUBSTITUTE(MID(C13,FIND("/",C13)+1,2)&"/"&LEFT(C13,2)&MID(C13,FIND("/",C13,4),5),"//","/") -> 12/10/2025 | V13: =DATEVALUE(U13) -> 45942
... A2425: ='CheshamLeyHill Transactions'!A2425 -> 0 | B2425: ='CheshamLeyHill Transactions'!B2425 -> 0 | C2425: ='CheshamLeyHill Transactions'!C2425 -> 0 | D2425: ='CheshamLeyHill Transactions'!D2425 -> 0 | E2425: ='CheshamLeyHill Transactions'!E2425 -> 0 | F2425: ='CheshamLeyHill Transactions'!F2425 -> 0 | G2425: ='CheshamLeyHill Transactions'!G2425 -> 0 | H2425: ='CheshamLeyHill Transactions'!H2425 -> 0 | ... T2425: ='CheshamLeyHill Transactions'!T2425 -> 0 | U2425: =SUBSTITUTE(MID(C2425,FIND("/",C2425)+1,2)&"/"&LEFT(C2425,2)&MID(C2425,FIND("/",C2425,4),5),"//","/") -> #VALUE! | V2425: =DATEVALUE(U2425) -> #VALUE!
A2426: ='CheshamLeyHill Transactions'!#REF! -> #REF! | B2426: ='CheshamLeyHill Transactions'!#REF! -> #REF! | C2426: ='CheshamLeyHill Transactions'!#REF! -> #REF! | D2426: ='CheshamLeyHill Transactions'!#REF! -> #REF! | E2426: ='CheshamLeyHill Transactions'!#REF! -> #REF! | F2426: ='CheshamLeyHill Transactions'!#REF! -> #REF! | G2426: ='CheshamLeyHill Transactions'!#REF! -> #REF! | H2426: ='CheshamLeyHill Transactions'!#REF! -> #REF! | ... T2426: ='CheshamLeyHill Transactions'!#REF! -> #REF! | U2426: =SUBSTITUTE(MID(C2426,FIND("/",C2426)+1,2)&"/"&LEFT(C2426,2)&MID(C2426,FIND("/",C2426,4),5),"//","/") -> #REF! | V2426: =DATEVALUE(U2426) -> #REF!
A2427: ='CheshamLeyHill Transactions'!A2426 -> 0 | B2427: ='CheshamLeyHill Transactions'!B2426 -> 0 | C2427: ='CheshamLeyHill Transactions'!C2426 -> 0 | D2427: ='CheshamLeyHill Transactions'!D2426 -> 0 | E2427: ='CheshamLeyHill Transactions'!E2426 -> 0 | F2427: ='CheshamLeyHill Transactions'!F2426 -> 0 | G2427: ='CheshamLeyHill Transactions'!G2426 -> 0 | H2427: ='CheshamLeyHill Transactions'!H2426 -> 0 | ... T2427: ='CheshamLeyHill Transactions'!T2426 -> 0 | U2427: =SUBSTITUTE(MID(C2427,FIND("/",C2427)+1,2)&"/"&LEFT(C2427,2)&MID(C2427,FIND("/",C2427,4),5),"//","/") -> #VALUE! | V2427: =DATEVALUE(U2427) -> #VALUE!
A2428: ='CheshamLeyHill Transactions'!A2427 -> 0 | B2428: ='CheshamLeyHill Transactions'!B2427 -> 0 | C2428: ='CheshamLeyHill Transactions'!C2427 -> 0 | D2428: ='CheshamLeyHill Transactions'!D2427 -> 0 | E2428: ='CheshamLeyHill Transactions'!E2427 -> 0 | F2428: ='CheshamLeyHill Transactions'!F2427 -> 0 | G2428: ='CheshamLeyHill Transactions'!G2427 -> 0 | H2428: ='CheshamLeyHill Transactions'!H2427 -> 0 | ... T2428: ='CheshamLeyHill Transactions'!T2427 -> 0 | U2428: =SUBSTITUTE(MID(C2428,FIND("/",C2428)+1,2)&"/"&LEFT(C2428,2)&MID(C2428,FIND("/",C2428,4),5),"//","/") -> #VALUE! | V2428: =DATEVALUE(U2428) -> #VALUE!
A2429: ='CheshamLeyHill Transactions'!A2428 -> 0 | B2429: ='CheshamLeyHill Transactions'!B2428 -> 0 | C2429: ='CheshamLeyHill Transactions'!C2428 -> 0 | D2429: ='CheshamLeyHill Transactions'!D2428 -> 0 | E2429: ='CheshamLeyHill Transactions'!E2428 -> 0 | F2429: ='CheshamLeyHill Transactions'!F2428 -> 0 | G2429: ='CheshamLeyHill Transactions'!G2428 -> 0 | H2429: ='CheshamLeyHill Transactions'!H2428 -> 0 | ... T2429: ='CheshamLeyHill Transactions'!T2428 -> 0 | U2429: =SUBSTITUTE(MID(C2429,FIND("/",C2429)+1,2)&"/"&LEFT(C2429,2)&MID(C2429,FIND("/",C2429,4),5),"//","/") -> #VALUE! | V2429: =DATEVALUE(U2429) -> #VALUE!
A2430: ='CheshamLeyHill Transactions'!A2429 -> 0 | B2430: ='CheshamLeyHill Transactions'!B2429 -> 0 | C2430: ='CheshamLeyHill Transactions'!C2429 -> 0 | D2430: ='CheshamLeyHill Transactions'!D2429 -> 0 | E2430: ='CheshamLeyHill Transactions'!E2429 -> 0 | F2430: ='CheshamLeyHill Transactions'!F2429 -> 0 | G2430: ='CheshamLeyHill Transactions'!G2429 -> 0 | H2430: ='CheshamLeyHill Transactions'!H2429 -> 0 | ... T2430: ='CheshamLeyHill Transactions'!T2429 -> 0 | U2430: =SUBSTITUTE(MID(C2430,FIND("/",C2430)+1,2)&"/"&LEFT(C2430,2)&MID(C2430,FIND("/",C2430,4),5),"//","/") -> #VALUE! | V2430: =DATEVALUE(U2430) -> #VALUE!
A2431: ='CheshamLeyHill Transactions'!A2430 -> 0 | B2431: ='CheshamLeyHill Transactions'!B2430 -> 0 | C2431: ='CheshamLeyHill Transactions'!C2430 -> 0 | D2431: ='CheshamLeyHill Transactions'!D2430 -> 0 | E2431: ='CheshamLeyHill Transactions'!E2430 -> 0 | F2431: ='CheshamLeyHill Transactions'!F2430 -> 0 | G2431: ='CheshamLeyHill Transactions'!G2430 -> 0 | H2431: ='CheshamLeyHill Transactions'!H2430 -> 0 | ... T2431: ='CheshamLeyHill Transactions'!T2430 -> 0 | U2431: =SUBSTITUTE(MID(C2431,FIND("/",C2431)+1,2)&"/"&LEFT(C2431,2)&MID(C2431,FIND("/",C2431,4),5),"//","/") -> #VALUE! | V2431: =DATEVALUE(U2431) -> #VALUE!
A2432: ='CheshamLeyHill Transactions'!A2431 -> 0 | B2432: ='CheshamLeyHill Transactions'!B2431 -> 0 | C2432: ='CheshamLeyHill Transactions'!C2431 -> 0 | D2432: ='CheshamLeyHill Transactions'!D2431 -> 0 | E2432: ='CheshamLeyHill Transactions'!E2431 -> 0 | F2432: ='CheshamLeyHill Transactions'!F2431 -> 0 | G2432: ='CheshamLeyHill Transactions'!G2431 -> 0 | H2432: ='CheshamLeyHill Transactions'!H2431 -> 0 | ... T2432: ='CheshamLeyHill Transactions'!T2431 -> 0 | U2432: =SUBSTITUTE(MID(C2432,FIND("/",C2432)+1,2)&"/"&LEFT(C2432,2)&MID(C2432,FIND("/",C2432,4),5),"//","/") -> #VALUE! | V2432: =DATEVALUE(U2432) -> #VALUE!
A2433: ='CheshamLeyHill Transactions'!A2432 -> 0 | B2433: ='CheshamLeyHill Transactions'!B2432 -> 0 | C2433: ='CheshamLeyHill Transactions'!C2432 -> 0 | D2433: ='CheshamLeyHill Transactions'!D2432 -> 0 | E2433: ='CheshamLeyHill Transactions'!E2432 -> 0 | F2433: ='CheshamLeyHill Transactions'!F2432 -> 0 | G2433: ='CheshamLeyHill Transactions'!G2432 -> 0 | H2433: ='CheshamLeyHill Transactions'!H2432 -> 0 | ... T2433: ='CheshamLeyHill Transactions'!T2432 -> 0 | U2433: =SUBSTITUTE(MID(C2433,FIND("/",C2433)+1,2)&"/"&LEFT(C2433,2)&MID(C2433,FIND("/",C2433,4),5),"//","/") -> #VALUE! | V2433: =DATEVALUE(U2433) -> #VALUE!
A2434: ='CheshamLeyHill Transactions'!A2433 -> 0 | B2434: ='CheshamLeyHill Transactions'!B2433 -> 0 | C2434: ='CheshamLeyHill Transactions'!C2433 -> 0 | D2434: ='CheshamLeyHill Transactions'!D2433 -> 0 | E2434: ='CheshamLeyHill Transactions'!E2433 -> 0 | F2434: ='CheshamLeyHill Transactions'!F2433 -> 0 | G2434: ='CheshamLeyHill Transactions'!G2433 -> 0 | H2434: ='CheshamLeyHill Transactions'!H2433 -> 0 | ... T2434: ='CheshamLeyHill Transactions'!T2433 -> 0 | U2434: =SUBSTITUTE(MID(C2434,FIND("/",C2434)+1,2)&"/"&LEFT(C2434,2)&MID(C2434,FIND("/",C2434,4),5),"//","/") -> #VALUE! | V2434: =DATEVALUE(U2434) -> #VALUE!
A2435: ='CheshamLeyHill Transactions'!A2434 -> 0 | B2435: ='CheshamLeyHill Transactions'!B2434 -> 0 | C2435: ='CheshamLeyHill Transactions'!C2434 -> 0 | D2435: ='CheshamLeyHill Transactions'!D2434 -> 0 | E2435: ='CheshamLeyHill Transactions'!E2434 -> 0 | F2435: ='CheshamLeyHill Transactions'!F2434 -> 0 | G2435: ='CheshamLeyHill Transactions'!G2434 -> 0 | H2435: ='CheshamLeyHill Transactions'!H2434 -> 0 | ... T2435: ='CheshamLeyHill Transactions'!T2434 -> 0 | U2435: =SUBSTITUTE(MID(C2435,FIND("/",C2435)+1,2)&"/"&LEFT(C2435,2)&MID(C2435,FIND("/",C2435,4),5),"//","/") -> #VALUE! | V2435: =DATEVALUE(U2435) -> #VALUE!
A2436: ='CheshamLeyHill Transactions'!A2435 -> 0 | B2436: ='CheshamLeyHill Transactions'!B2435 -> 0 | C2436: ='CheshamLeyHill Transactions'!C2435 -> 0 | D2436: ='CheshamLeyHill Transactions'!D2435 -> 0 | E2436: ='CheshamLeyHill Transactions'!E2435 -> 0 | F2436: ='CheshamLeyHill Transactions'!F2435 -> 0 | G2436: ='CheshamLeyHill Transactions'!G2435 -> 0 | H2436: ='CheshamLeyHill Transactions'!H2435 -> 0 | ... T2436: ='CheshamLeyHill Transactions'!T2435 -> 0 | U2436: =SUBSTITUTE(MID(C2436,FIND("/",C2436)+1,2)&"/"&LEFT(C2436,2)&MID(C2436,FIND("/",C2436,4),5),"//","/") -> #VALUE! | V2436: =DATEVALUE(U2436) -> #VALUE!
A2437: ='CheshamLeyHill Transactions'!A2436 -> 0 | B2437: ='CheshamLeyHill Transactions'!B2436 -> 0 | C2437: ='CheshamLeyHill Transactions'!C2436 -> 0 | D2437: ='CheshamLeyHill Transactions'!D2436 -> 0 | E2437: ='CheshamLeyHill Transactions'!E2436 -> 0 | F2437: ='CheshamLeyHill Transactions'!F2436 -> 0 | G2437: ='CheshamLeyHill Transactions'!G2436 -> 0 | H2437: ='CheshamLeyHill Transactions'!H2436 -> 0 | ... T2437: ='CheshamLeyHill Transactions'!T2436 -> 0 | U2437: =SUBSTITUTE(MID(C2437,FIND("/",C2437)+1,2)&"/"&LEFT(C2437,2)&MID(C2437,FIND("/",C2437,4),5),"//","/") -> #VALUE! | V2437: =DATEVALUE(U2437) -> #VALUE!
A2438: ='CheshamLeyHill Transactions'!A2437 -> 0 | B2438: ='CheshamLeyHill Transactions'!B2437 -> 0 | C2438: ='CheshamLeyHill Transactions'!C2437 -> 0 | D2438: ='CheshamLeyHill Transactions'!D2437 -> 0 | E2438: ='CheshamLeyHill Transactions'!E2437 -> 0 | F2438: ='CheshamLeyHill Transactions'!F2437 -> 0 | G2438: ='CheshamLeyHill Transactions'!G2437 -> 0 | H2438: ='CheshamLeyHill Transactions'!H2437 -> 0 | ... T2438: ='CheshamLeyHill Transactions'!T2437 -> 0 | U2438: =SUBSTITUTE(MID(C2438,FIND("/",C2438)+1,2)&"/"&LEFT(C2438,2)&MID(C2438,FIND("/",C2438,4),5),"//","/") -> #VALUE! | V2438: =DATEVALUE(U2438) -> #VALUE!
... A6853: ='CheshamLeyHill Transactions'!A6852 -> 0 | B6853: ='CheshamLeyHill Transactions'!B6852 -> 0 | C6853: ='CheshamLeyHill Transactions'!C6852 -> 0 | D6853: ='CheshamLeyHill Transactions'!D6852 -> 0 | E6853: ='CheshamLeyHill Transactions'!E6852 -> 0 | F6853: ='CheshamLeyHill Transactions'!F6852 -> 0 | G6853: ='CheshamLeyHill Transactions'!G6852 -> 0 | H6853: ='CheshamLeyHill Transactions'!H6852 -> 0 | ... T6853: ='CheshamLeyHill Transactions'!T6852 -> 0 | U6853: =SUBSTITUTE(MID(C6853,FIND("/",C6853)+1,2)&"/"&LEFT(C6853,2)&MID(C6853,FIND("/",C6853,4),5),"//","/") -> #VALUE! | V6853: =DATEVALUE(U6853) -> #VALUE!

Sheet Instructions
B1: To Upload new data
A2: 1 | B2: Run 'Transaction Report' in Epos system
A3: 2 | B3: Only choose 1 day to report on at a time
A4: 3 | B4: Export 'Transaction Report' as a CSV file
A5: 4 | B5: Open Excel, and open the CSV file
A6: 5 | B6: On the Import Wizard, select Delimited as the type of data, click Next
A7: 6 | B7: Select Comma as the delimiter, click Next
B8: Highlight the Date complete column and select Text as the data format, click Finish
B9: Copy from row 2 down to the last row
B10: Paste the data into the 'Transactions' tab
B11: To add another day follow the above steps and paste the data into the next free row at the bottom of the 'Transactions' tab
B14: To use Dashboard Tab
B15: Simply change the start date and end date in the fields with the Red background
B16: For best results run for individual days
B17: Create a new file every month to keep the file size smaller and improve speed
